
# clear builtins._
# clear sys.path
# clear sys.argv
# clear sys.ps1
# clear sys.ps2
# clear sys.last_type
# clear sys.last_value
# clear sys.last_traceback
# clear sys.path_hooks
# clear sys.path_importer_cache
# clear sys.meta_path
# clear sys.__interactivehook__
# restore sys.stdin
# restore sys.stdout
# restore sys.stderr
# clear builtins._
# clear sys.path
# clear sys.argv
# clear sys.ps1
# clear sys.ps2
# clear sys.last_type
# clear sys.last_value
# clear sys.last_traceback
# clear sys.path_hooks
# clear sys.path_importer_cache
# clear sys.meta_path
# clear sys.__interactivehook__
# restore sys.stdin
# restore sys.stdout
# restore sys.stderr
Exception in Tkinter callback
Traceback (most recent call last):
  File "/usr/lib64/python3.9/tkinter/__init__.py", line 1889, in __call__
    try:
KeyboardInterrupt
Exception in Tkinter callback
Traceback (most recent call last):
  File "/usr/lib64/python3.9/tkinter/__init__.py", line 1889, in __call__
    try:
KeyboardInterrupt
# clear builtins._
# clear sys.path
# clear sys.argv
# clear sys.ps1
# clear sys.ps2
# clear sys.last_type
# clear sys.last_value
# clear sys.last_traceback
# clear sys.path_hooks
# clear sys.path_importer_cache
# clear sys.meta_path
# clear sys.__interactivehook__
# restore sys.stdin
# restore sys.stdout
# restore sys.stderr
# clear builtins._
# clear sys.path
# clear sys.argv
# clear sys.ps1
# clear sys.ps2
# clear sys.last_type
# clear sys.last_value
# clear sys.last_traceback
# clear sys.path_hooks
# clear sys.path_importer_cache
# clear sys.meta_path
# clear sys.__interactivehook__
# restore sys.stdin
# restore sys.stdout
# restore sys.stderr
# clear builtins._
# clear sys.path
# clear sys.argv
# clear sys.ps1
# clear sys.ps2
# clear sys.last_type
# clear sys.last_value
# clear sys.last_traceback
# clear sys.path_hooks
# clear sys.path_importer_cache
# clear sys.meta_path
# clear sys.__interactivehook__
# restore sys.stdin
# restore sys.stdout
# restore sys.stderr
# clear builtins._
# clear sys.path
# clear sys.argv
# clear sys.ps1
# clear sys.ps2
# clear sys.last_type
# clear sys.last_value
# clear sys.last_traceback
# clear sys.path_hooks
# clear sys.path_importer_cache
# clear sys.meta_path
# clear sys.__interactivehook__
# restore sys.stdin
# restore sys.stdout
# restore sys.stderr
# clear builtins._
# clear sys.path
# clear sys.argv
# clear sys.ps1
# clear sys.ps2
# clear sys.last_type
# clear sys.last_value
# clear sys.last_traceback
# clear sys.path_hooks
# clear sys.path_importer_cache
# clear sys.meta_path
# clear sys.__interactivehook__
# restore sys.stdin
# restore sys.stdout
# restore sys.stderr
# clear builtins._
# clear sys.path
# clear sys.argv
# clear sys.ps1
# clear sys.ps2
# clear sys.last_type
# clear sys.last_value
# clear sys.last_traceback
# clear sys.path_hooks
# clear sys.path_importer_cache
# clear sys.meta_path
# clear sys.__interactivehook__
# restore sys.stdin
# restore sys.stdout
# restore sys.stderr
# clear builtins._
# clear sys.path
# clear sys.argv
# clear sys.ps1
# clear sys.ps2
# clear sys.last_type
# clear sys.last_value
# clear sys.last_traceback
# clear sys.path_hooks
# clear sys.path_importer_cache
# clear sys.meta_path
# clear sys.__interactivehook__
# restore sys.stdin
# restore sys.stdout
# restore sys.stderr
# clear builtins._
# clear sys.path
# clear sys.argv
# clear sys.ps1
# clear sys.ps2
# clear sys.last_type
# clear sys.last_value
# clear sys.last_traceback
# clear sys.path_hooks
# clear sys.path_importer_cache
# clear sys.meta_path
# clear sys.__interactivehook__
# restore sys.stdin
# restore sys.stdout
# restore sys.stderr
Traceback (most recent call last):
  File "/usr/lib64/python3.9/tkinter/__init__.py", line 1892, in __call__
    return self.func(*args)
  File "/mnt/production/user/george.antonopoulos/DEV/ffmpeg_convert/ffmpeg_ui.py", line 638, in run_ffmpeg
    set_nonblocking(process.stderr)
KeyboardInterrupt

During handling of the above exception, another exception occurred:

Traceback (most recent call last):
  File "/mnt/production/user/george.antonopoulos/DEV/ffmpeg_convert/ffmpeg_ui.py", line 969, in <module>
    try:
  File "/usr/lib64/python3.9/tkinter/__init__.py", line 1429, in mainloop
    self.tk.mainloop(n)
  File "/usr/lib64/python3.9/tkinter/__init__.py", line 1896, in __call__
    self.widget._report_exception()
  File "/usr/lib64/python3.9/tkinter/__init__.py", line 1612, in _report_exception
    root.report_callback_exception(exc, val, tb)
  File "/usr/lib64/python3.9/tkinter/__init__.py", line 2345, in report_callback_exception
    import traceback
  File "<frozen importlib._bootstrap>", line 1007, in _find_and_load
  File "<frozen importlib._bootstrap>", line 982, in _find_and_load_unlocked
  File "<frozen importlib._bootstrap>", line 917, in _find_spec
  File "<frozen importlib._bootstrap>", line 874, in __enter__
KeyboardInterrupt
Traceback (most recent call last):
  File "/usr/lib64/python3.9/tkinter/__init__.py", line 1892, in __call__
    return self.func(*args)
  File "/mnt/production/user/george.antonopoulos/DEV/ffmpeg_convert/ffmpeg_ui.py", line 677, in run_ffmpeg
    file_extension = ".mp4" if codec in ["h264", "h265"] else ".mov"
KeyboardInterrupt

During handling of the above exception, another exception occurred:

Traceback (most recent call last):
  File "/mnt/production/user/george.antonopoulos/DEV/ffmpeg_convert/ffmpeg_ui.py", line 994, in <module>
    new_pattern = f"{before}%04d.png"
  File "/usr/lib64/python3.9/tkinter/__init__.py", line 1429, in mainloop
    self.tk.mainloop(n)
  File "/usr/lib64/python3.9/tkinter/__init__.py", line 1896, in __call__
    self.widget._report_exception()
  File "/usr/lib64/python3.9/tkinter/__init__.py", line 1612, in _report_exception
    root.report_callback_exception(exc, val, tb)
  File "/usr/lib64/python3.9/tkinter/__init__.py", line 2345, in report_callback_exception
    import traceback
  File "<frozen importlib._bootstrap>", line 1007, in _find_and_load
  File "<frozen importlib._bootstrap>", line 982, in _find_and_load_unlocked
  File "<frozen importlib._bootstrap>", line 925, in _find_spec
  File "<frozen importlib._bootstrap_external>", line 1424, in find_spec
  File "<frozen importlib._bootstrap_external>", line 1396, in _get_spec
  File "<frozen importlib._bootstrap_external>", line 1523, in find_spec
  File "<frozen importlib._bootstrap_external>", line 142, in _path_stat
KeyboardInterrupt
Exception in thread Thread-1:
Traceback (most recent call last):
  File "/usr/lib64/python3.9/threading.py", line 980, in _bootstrap_inner
    self.run()
  File "/usr/lib64/python3.9/threading.py", line 917, in run
    self._target(*self._args, **self._kwargs)
  File "/mnt/production/user/george.antonopoulos/DEV/ffmpeg_convert/ffmpeg_ui.py", line 892, in convert_exr_files
    self.temp_dir = os.path.join("/tmp", f"ffmpeg_convert_{os.getpid()}")
UnboundLocalError: local variable 'os' referenced before assignment
Exception in thread Thread-2:
Traceback (most recent call last):
  File "/usr/lib64/python3.9/threading.py", line 980, in _bootstrap_inner
    self.run()
  File "/usr/lib64/python3.9/threading.py", line 917, in run
    self._target(*self._args, **self._kwargs)
  File "/mnt/production/user/george.antonopoulos/DEV/ffmpeg_convert/ffmpeg_ui.py", line 892, in convert_exr_files
    self.temp_dir = os.path.join("/tmp", f"ffmpeg_convert_{os.getpid()}")
UnboundLocalError: local variable 'os' referenced before assignment
Exception in thread Thread-3:
Traceback (most recent call last):
  File "/usr/lib64/python3.9/threading.py", line 980, in _bootstrap_inner
    self.run()
  File "/usr/lib64/python3.9/threading.py", line 917, in run
    self._target(*self._args, **self._kwargs)
  File "/mnt/production/user/george.antonopoulos/DEV/ffmpeg_convert/ffmpeg_ui.py", line 892, in convert_exr_files
    self.temp_dir = os.path.join("/tmp", f"ffmpeg_convert_{os.getpid()}")
UnboundLocalError: local variable 'os' referenced before assignment
Exception in Tkinter callback
Traceback (most recent call last):
  File "/usr/lib64/python3.9/tkinter/__init__.py", line 1889, in __call__
    try:
KeyboardInterrupt
Exception in Tkinter callback
Traceback (most recent call last):
  File "/usr/lib64/python3.9/tkinter/__init__.py", line 1889, in __call__
    try:
KeyboardInterrupt
Exception ignored in: <module 'threading' from '/usr/lib64/python3.9/threading.py'>
Traceback (most recent call last):
  File "/usr/lib64/python3.9/threading.py", line 1477, in _shutdown
KeyboardInterrupt: 
Exception in Tkinter callback
Traceback (most recent call last):
  File "/usr/lib64/python3.9/tkinter/__init__.py", line 1889, in __call__
    try:
KeyboardInterrupt
Exception ignored in: <module 'threading' from '/usr/lib64/python3.9/threading.py'>
Traceback (most recent call last):
  File "/usr/lib64/python3.9/threading.py", line 1477, in _shutdown
KeyboardInterrupt: 
Exception ignored in: Exception ignored in sys.unraisablehook: <built-in function unraisablehook>
Traceback (most recent call last):
  File "/mnt/production/user/george.antonopoulos/DEV/ffmpeg_convert/ffmpeg_ui.py", line 26, in write
    self.file.flush()
  File "/mnt/production/user/george.antonopoulos/DEV/ffmpeg_convert/ffmpeg_ui.py", line 1188, in signal_handler
    
SystemExit: 0
Exception ignored in: <module 'threading' from '/usr/lib64/python3.9/threading.py'>
Traceback (most recent call last):
  File "/usr/lib64/python3.9/threading.py", line 1477, in _shutdown
    lock.acquire()
  File "/mnt/production/user/george.antonopoulos/DEV/ffmpeg_convert/ffmpeg_ui.py", line 1203, in signal_handler
    # Force kill as last resort
SystemExit: 0
Exception ignored in: Exception ignored in sys.unraisablehook: <built-in function unraisablehook>
Traceback (most recent call last):
  File "/mnt/production/user/george.antonopoulos/DEV/ffmpeg_convert/ffmpeg_ui.py", line 26, in write
    self.file.flush()
  File "/mnt/production/user/george.antonopoulos/DEV/ffmpeg_convert/ffmpeg_ui.py", line 1159, in signal_handler
    # Set the frame range and total frames for FFmpeg.
SystemExit: 0
Exception ignored in: <module 'threading' from '/usr/lib64/python3.9/threading.py'>
Traceback (most recent call last):
  File "/usr/lib64/python3.9/threading.py", line 1477, in _shutdown
    lock.acquire()
  File "/mnt/production/user/george.antonopoulos/DEV/ffmpeg_convert/ffmpeg_ui.py", line 1213, in signal_handler
    sys.exit(0)
SystemExit: 0
